Workbook

Sheet INDEX
A1: INDEX | E1: Valuation | L1: F2027
A2: NSE Code | B2: Vadilal Enterprise LTD. | E2: Forward PE | L2: =L5/'Formated PL'!H35 -> 474.36228
A3: Bse Code | B3: 519152 | E3: Average PE | L3: 43.5
A4: Market Cap | B4: 862.58 | E4: Target Price as per PE | L4: =L3*'Formated PL'!H35 -> 916.92893
A5: Macro-Economic Indicator | B5: Fast Moving Consumer Goods | E5: Current Price | L5: 9999
A6: Sector | B6: Fast Moving Consumer Goods | E6: Upside/Downside | L6: =L4/L5-1 -> -0.90829794
A7: Industry | B7: Food Products | E7: Average EV/EBITDA | L7: 12.5
A8: Basic Industry | B8: Dairy Products | E8: EV | L8: =L7*'Formated PL'!H18 -> 562.69295
A9: Index | E9: Less :Debt | L9: =BS!F42+BS!F35 -> 45.24
A10: 52 High/low | B10: 14,620.55/7,800.00 | E10: Add Cash | L10: =BS!F20 -> 11.66
E11: Equity Value | L11: =L8-L9+L10 -> 529.11295
E12: Target Price as per EV/EBITDA ( Value per share) | L12: =L11/'Formated PL'!H34 -> 615.24762
E13: Upside/ downside | L13: =L12/L5-1 -> -0.93846908

Sheet BS
A1: CHECK | B1: =B26-B53 -> 0 | C1: =C26-C53 -> 0 | D1: =D26-D53 -> 0 | E1: =E26-E53 -> 0 | F1: =F26-F53 -> 0 | G1: =G26-G53 -> 0.0002 | H1: =H26-H53 -> 0.0002 | I1: =I26-I53 -> 0.0002 | ... K1: =K26-K53 -> 0.0002
A2: Particulars | B2: ='Formated PL'!B2 -> 2021 | C2: ='Formated PL'!C2 -> 2022 | D2: ='Formated PL'!D2 -> 2023 | E2: ='Formated PL'!E2 -> 2024 | F2: ='Formated PL'!F2 -> 2025 | G2: ='Formated PL'!G2 -> F2026 | H2: ='Formated PL'!H2 -> F2027 | I2: ='Formated PL'!I2 -> F2028 | ... K2: ='Formated PL'!K2 -> F2030
A3: ASSETS
A4: Non-Current Assets
A5: Property,Plant And Equipment | B5: 57.1819 | C5: 46.382 | D5: 41.62 | E5: 65.75 | F5: 94.58 | G5: ='PPE NOTE'!E16 -> 101.49618 | H5: ='PPE NOTE'!F16 -> 108.59928 | I5: ='PPE NOTE'!G16 -> 115.90846 | J5: ='PPE NOTE'!H16 -> 123.44484 | K5: ='PPE NOTE'!I16 -> 131.23171
A6: Capital Work-In-Progress | B6: 0.0332 | C6: 0.1023 | D6: 11.75 | E6: 18.79 | F6: 18.14 | G6: 18.14 | H6: 18.14 | I6: 18.14 | J6: 18.14 | K6: 18.14
A7: Other Intangible Assets | B7: 1.0854 | C7: 0.9321 | D7: 0.56 | E7: 0.26 | F7: 0.32 | G7: 0.32 | H7: 0.32 | I7: 0.32 | J7: 0.32 | K7: 0.32
A8: Right of use assets | D8: 1.83 | E8: 2.22 | F8: 1.93 | G8: 1.93 | H8: 1.93 | I8: 1.93 | J8: 1.93 | K8: 1.93
A9: Financial Assets
A10: Investments | B10: 0.1294 | C10: 0.2126 | D10: 0.29 | E10: 0.42 | F10: 0.42 | G10: 0.42 | H10: 0.42 | I10: 0.42 | J10: 0.42 | K10: 0.42
A11: Loans | B11: 0.0626 | C11: 0.0542 | D11: 0.05 | E11: 0.13 | F11: 0.24 | G11: 0.24 | H11: 0.24 | I11: 0.24 | J11: 0.24 | K11: 0.24
A12: Other Financial Assets | B12: 14.2162 | C12: 15.2571 | D12: 18.82 | E12: 19.37 | F12: 20.07 | G12: 20.07 | H12: 20.07 | I12: 20.07 | J12: 20.07 | K12: 20.07
A13: Deferred Tax Assets (Net) | B13: 3.212 | C13: 3.0849 | D13: 3.9 | E13: 3.4 | F13: 3.5 | G13: 3.5 | H13: 3.5 | I13: 3.5 | J13: 3.5 | K13: 3.5
A14: Other Non-Current Assets | B14: 6.3881 | C14: 5.5394 | D14: 4.24 | E14: 3.32 | F14: 5.35 | G14: 5.35 | H14: 5.35 | I14: 5.35 | J14: 5.35 | K14: 5.35
A15: Total Non-Current Assets | B15: =SUM(B5:B14) -> 82.3088 | C15: =SUM(C5:C14) -> 71.5646 | D15: =SUM(D5:D14) -> 83.06 | E15: =SUM(E5:E14) -> 113.66 | F15: =SUM(F5:F14) -> 144.55 | G15: =SUM(G5:G14) -> 151.46618 | H15: =SUM(H5:H14) -> 158.56928 | I15: =SUM(I5:I14) -> 165.87846 | ... K15: =SUM(K5:K14) -> 181.20171
A16: Current Assets
A17: Inventories | B17: 28.0477 | C17: 33.7302 | D17: 49.1 | E17: 48.12 | F17: 41.52 | G17: ='WC Note'!G9 -> 44.649119 | H17: ='WC Note'!H9 -> 49.225654 | I17: ='WC Note'!I9 -> 54.271283 | J17: ='WC Note'!J9 -> 59.83409 | K17: ='WC Note'!K9 -> 65.967084
A18: Financial Assets
A19: Trade Receivables | B19: 26.8101 | C19: 15.3965 | D19: 38.47 | E19: 47.99 | F19: 57.28 | G19: ='WC Note'!G8 -> 63.1512 | H19: ='WC Note'!H8 -> 69.624198 | I19: ='WC Note'!I8 -> 76.760678 | J19: ='WC Note'!J8 -> 84.628648 | K19: ='WC Note'!K8 -> 93.303084
A20: Cash And Cash Equivalents | B20: 0.3887 | C20: 5.0839 | D20: 7.04 | E20: 6.22 | F20: 11.66 | G20: =CF!G41 -> 22.545141 | H20: =CF!H41 -> 34.110438 | I20: =CF!I41 -> 44.329747 | J20: =CF!J41 -> 52.636565 | K20: =CF!K41 -> 58.33776
A21: Bank Balance Other Than (ii) Above | B21: 0.545 | C21: 2.0736 | D21: 2.05 | E21: 0.67 | F21: 10.6 | G21: 10.6 | H21: 10.6 | I21: 10.6 | J21: 10.6 | K21: 10.6
A22: Loans | B22: 0.0945 | C22: 0.1397 | D22: 0.12 | E22: 0.19 | F22: 0.32 | G22: 0.32 | H22: 0.32 | I22: 0.32 | J22: 0.32 | K22: 0.32
A23: Other Financial Assets | B23: 0.2014 | C23: 0.18 | D23: 0.18 | E23: 0.28 | F23: 0.39 | G23: 0.39 | H23: 0.39 | I23: 0.39 | J23: 0.39 | K23: 0.39
A24: Other Current Assets | B24: 5.4621 | C24: 5.3027 | D24: 10.65 | E24: 13.66 | F24: 14.24 | G24: 14.24 | H24: 14.24 | I24: 14.24 | J24: 14.24 | K24: 14.24
A25: Total Current Assets | B25: =SUM(B17:B24) -> 61.5495 | C25: =SUM(C17:C24) -> 61.9066 | D25: =SUM(D17:D24) -> 107.61 | E25: =SUM(E17:E24) -> 117.13 | F25: =SUM(F17:F24) -> 136.01 | G25: =SUM(G17:G24) -> 155.89546 | H25: =SUM(H17:H24) -> 178.51029 | I25: =SUM(I17:I24) -> 200.91171 | ... K25: =SUM(K17:K24) -> 243.15793
A26: TOTAL ASSETS | B26: =B25+B15 -> 143.8583 | C26: =C25+C15 -> 133.4712 | D26: =D25+D15 -> 190.67 | E26: =E25+E15 -> 230.79 | F26: =F25+F15 -> 280.56 | G26: =G25+G15 -> 307.36164 | H26: =H25+H15 -> 337.07957 | I26: =I25+I15 -> 366.79017 | ... K26: =K25+K15 -> 424.35964
A27: EQUITY AND LIABILITIES
A28: Equity
A29: Equity Share capital | B29: 0.8627 | C29: 0.8627 | D29: 0.86 | E29: 0.86 | F29: 0.86 | G29: 0.86 | H29: 0.86 | I29: 0.86 | J29: 0.86 | K29: 0.86
A30: Other Equity | B30: 2.7236 | C30: 4.4239 | D30: 10.2 | E30: 17.2 | F30: 21.41 | G30: ='Other Equity'!G5 -> 40.286901 | H30: ='Other Equity'!H5 -> 58.414692 | I30: ='Other Equity'!I5 -> 75.347159 | J30: ='Other Equity'!J5 -> 90.533244 | K30: ='Other Equity'!K5 -> 103.29684
A31: Total Equity | B31: =SUM(B29:B30) -> 3.5863 | C31: =SUM(C29:C30) -> 5.2866 | D31: =SUM(D29:D30) -> 11.06 | E31: =SUM(E29:E30) -> 18.06 | F31: =SUM(F29:F30) -> 22.27 | G31: =SUM(G29:G30) -> 41.146901 | H31: =SUM(H29:H30) -> 59.274692 | I31: =SUM(I29:I30) -> 76.207159 | ... K31: =SUM(K29:K30) -> 104.15684
A32: Liabilities
A33: Non-Current Liabilities
A34: Financial Liabilities
A35: Borrowings | B35: 2.347 | C35: 2.8398 | D35: 2.72 | E35: 16.21 | F35: 29.73 | G35: 29.73 | H35: 29.73 | I35: 29.73 | J35: 29.73 | K35: 29.73
A36: Lease Liabilities | D36: 1.78 | E36: 2.23 | F36: 2 | G36: 2 | H36: 2 | I36: 2 | J36: 2 | K36: 2
A37: Other Financial Liabilities | B37: 0.071 | C37: 0.046 | D37: 0.02
A38: Provisions | B38: 0.9421 | C38: 1.2293 | D38: 0.93 | F38: 0.46 | G38: 0.46 | H38: 0.46 | I38: 0.46 | J38: 0.46 | K38: 0.46
A39: Total Non-Current Liabilities | B39: =SUM(B34:B38) -> 3.3601 | C39: =SUM(C34:C38) -> 4.1151 | D39: =SUM(D34:D38) -> 5.45 | E39: =SUM(E34:E38) -> 18.44 | F39: =SUM(F34:F38) -> 32.19 | G39: =SUM(G34:G38) -> 32.19 | H39: =SUM(H34:H38) -> 32.19 | I39: =SUM(I34:I38) -> 32.19 | ... K39: =SUM(K34:K38) -> 32.19
A40: Current Liabilities
...

Sheet CF
A1: Particulars | B1: ='Formated PL'!B2 -> 2021 | C1: ='Formated PL'!C2 -> 2022 | D1: ='Formated PL'!D2 -> 2023 | E1: ='Formated PL'!E2 -> 2024 | F1: ='Formated PL'!F2 -> 2025 | G1: ='Formated PL'!G2 -> F2026 | H1: ='Formated PL'!H2 -> F2027 | I1: ='Formated PL'!I2 -> F2028 | ... K1: ='Formated PL'!K2 -> F2030
A2: CASH FLOWS FROM OPERATING ACTIVITIES
A3: Profit before tax | B3: 1.2279 | C3: 3.0011 | D3: 8.6 | E3: 10.05 | F3: 7.62 | G3: ='Formated PL'!G31 -> 18.876901 | H3: ='Formated PL'!H31 -> 18.12779 | I3: ='Formated PL'!I31 -> 16.932467 | J3: ='Formated PL'!J31 -> 15.186086 | K3: ='Formated PL'!K31 -> 12.763598
A4: Adjustments for:
A5: Depreciation and Amortisation expense | B5: 13.27 | C5: 11.74 | D5: 11.07 | E5: 12.4 | F5: 16.13 | G5: ='PPE NOTE'!E11 -> 17.760415 | H5: ='PPE NOTE'!F11 -> 20.102847 | I5: ='PPE NOTE'!G11 -> 22.685378 | J5: ='PPE NOTE'!H11 -> 25.532619 | K5: ='PPE NOTE'!I11 -> 28.671702
A6: Loss/(Profit) on sale of Property, Plant & Equipment (net) | B6: 0.48 | C6: -0.52 | D6: 0.22 | E6: 0.76 | F6: 0.93
A7: Interest Income | B7: -1.8 | C7: -1.24 | D7: -1.66 | E7: -1.16 | F7: -1.57
A8: Finance Costs | B8: 4.83 | C8: 2.17 | D8: 1.34 | E8: 3.5 | F8: 6.14
A9: Loss/(Profit) from Sale of Current Investments | B9: -0.09 | C9: -0.05 | D9: -1.06 | E9: -1.07 | F9: -2.13
A10: Change in Fair value of the Current Investment | B10: -0.01 | C10: -0.08 | D10: -0.08 | E10: -0.12
A11: Provision for Doubtful Debts | E11: 0.49 | F11: 0.04
A12: Excess Provision/Credit Balance/Deposits written back | B12: -1.47 | C12: -1.76 | D12: -8.83 | E12: -9 | F12: -1.32
A13: Excess Provision for Trade Receivables | B13: -0.16 | C13: -0.47 | D13: -0.25 | F13: -0.19
A14: Scrap Sale of asset | B14: -0.5 | C14: -0.36 | D14: -0.68 | E14: -0.87 | F14: -0.99
A15: Bad Debts Written off | B15: 0.02 | C15: 0.16 | D15: 0.29 | E15: 0.04 | F15: 0.55
B16: =SUM(B5:B15) -> 14.57 | C16: =SUM(C5:C15) -> 9.59 | D16: =SUM(D5:D15) -> 0.36 | E16: =SUM(E5:E15) -> 4.97 | F16: =SUM(F5:F15) -> 17.59 | G16: =SUM(G5:G15) -> 17.760415 | H16: =SUM(H5:H15) -> 20.102847 | I16: =SUM(I5:I15) -> 22.685378 | ... K16: =SUM(K5:K15) -> 28.671702
A17: Operating Profit before Working Capital changes | B17: =B16+B3 -> 15.7979 | C17: =C16+C3 -> 12.5911 | D17: =D16+D3 -> 8.96 | E17: =E16+E3 -> 15.02 | F17: =F16+F3 -> 25.21 | G17: =G16+G3 -> 36.637316 | H17: =H16+H3 -> 38.230637 | I17: =I16+I3 -> 39.617845 | ... K17: =K16+K3 -> 41.4353
A18: Changes in Working Capital:
A19: (Increase)/Decrease in Inventories | B19: -2.69 | C19: ='WC Note'!B9-'WC Note'!C9 -> -5.6825 | D19: ='WC Note'!C9-'WC Note'!D9 -> -15.3698 | E19: ='WC Note'!D9-'WC Note'!E9 -> 0.98 | F19: ='WC Note'!E9-'WC Note'!F9 -> 6.6 | G19: ='WC Note'!F9-'WC Note'!G9 -> -3.1291191 | H19: ='WC Note'!G9-'WC Note'!H9 -> -4.5765347 | I19: ='WC Note'!H9-'WC Note'!I9 -> -5.0456295 | J19: ='WC Note'!I9-'WC Note'!J9 -> -5.5628065 | K19: ='WC Note'!J9-'WC Note'!K9 -> -6.1329942
A20: (Increase)/Decrease in Trade receivables, financial assets and other assets | B20: 3.35 | C20: 11.25 | D20: -12.13 | E20: -10.67 | F20: -22.33 | G20: ='WC Note'!F8-'WC Note'!G8 -> -5.8712 | H20: ='WC Note'!G8-'WC Note'!H8 -> -6.472998 | I20: ='WC Note'!H8-'WC Note'!I8 -> -7.1364803 | J20: ='WC Note'!I8-'WC Note'!J8 -> -7.8679695 | K20: ='WC Note'!J8-'WC Note'!K8 -> -8.6744364
A21: Increase/(Decrease) in Trade Payables, financial liabilities, other liabilities and provisions | B21: -1.54 | C21: 7.41 | D21: 26.67 | E21: 15.72 | F21: 25.25 | G21: ='WC Note'!G10-'WC Note'!F10 -> 7.9245394 | H21: ='WC Note'!H10-'WC Note'!G10 -> 11.59014 | I21: ='WC Note'!I10-'WC Note'!H10 -> 12.77813 | J21: ='WC Note'!J10-'WC Note'!I10 -> 14.087888 | K21: ='WC Note'!K10-'WC Note'!J10 -> 15.531896
A22: Cash Generated from/(Used in) Operations | B22: =SUM(B19:B21) -> -0.88 | C22: =SUM(C19:C21) -> 12.9775 | D22: =SUM(D19:D21) -> -0.8298 | E22: =SUM(E19:E21) -> 6.03 | F22: =SUM(F19:F21) -> 9.52 | G22: =SUM(G19:G21) -> -1.0757798 | H22: =SUM(H19:H21) -> 0.54060758 | I22: =SUM(I19:I21) -> 0.59601985 | ... K22: =SUM(K19:K21) -> 0.72446585
A23: Income Tax paid | B23: -0.15 | C23: -1.18 | D23: -1 | E23: -3.72 | F23: -2.63
A24: Net Cash Generated from / (Used in) operating activities (A) | B24: =SUM(B22:B23,B17) -> 14.7679 | C24: =SUM(C22:C23,C17) -> 24.3886 | D24: =SUM(D22:D23,D17) -> 7.1302 | E24: =SUM(E22:E23,E17) -> 17.33 | F24: =SUM(F22:F23,F17) -> 32.1 | G24: =SUM(G22:G23,G17) -> 35.561537 | H24: =SUM(H22:H23,H17) -> 38.771245 | I24: =SUM(I22:I23,I17) -> 40.213865 | ... K24: =SUM(K22:K23,K17) -> 42.159766
A25: CASH FLOWS FROM INVESTING ACTIVITIES
A26: Capital Expenditure on Property, Plant & Equipment & Intangible asset | B26: -3.99 | C26: -13.38 | D26: -6.63 | E26: -38.2 | F26: -43.96 | G26: =-'PPE NOTE'!E4 -> -24.676596 | H26: =-'PPE NOTE'!F4 -> -27.205947 | I26: =-'PPE NOTE'!G4 -> -29.994557 | J26: =-'PPE NOTE'!H4 -> -33.068999 | K26: =-'PPE NOTE'!I4 -> -36.458571
A27: Proceeds from Sale of Property, Plant & Equipment | B27: 3.41 | C27: 2.84 | D27: 2.26 | E27: 1.83 | F27: 1.78
A28: Proceeds / (Purchase) from Sale of Current Investments (Net) | B28: 0.09 | C28: 0.05 | D28: 1.06 | E28: 1.06 | F28: 2.13
A29: Interest received | B29: 1.82 | C29: 0.26 | D29: 0.31 | E29: 0.27 | F29: 0.62
A30: Net Cash Generated from / (used in) Investing Activities (B) | B30: =SUM(B26:B29) -> 1.33 | C30: =SUM(C26:C29) -> -10.23 | D30: =SUM(D26:D29) -> -3 | E30: =SUM(E26:E29) -> -35.04 | F30: =SUM(F26:F29) -> -39.43 | G30: =SUM(G26:G29) -> -24.676596 | H30: =SUM(H26:H29) -> -27.205947 | I30: =SUM(I26:I29) -> -29.994557 | ... K30: =SUM(K26:K29) -> -36.458571
A31: CASH FLOWS FROM FINANCING ACTIVITIES
A32: Proceeds from Non Current borrowings | B32: 1.57 | C32: 3.22 | D32: 3.94 | E32: 26.75 | F32: 45.88
A33: Repayment of Non Current borrowings | B33: -5.32 | C33: -7.69 | D33: -5.5 | E33: -5.47 | F33: -25.91
A34: Proceeds from /(Repayment of ) Current borrowings (Net) | B34: -8.47 | C34: -2.12 | D34: 0.93 | E34: -0.53 | F34: -0.56
A35: Payment of Lease liabilities | D35: -0.09 | E35: -0.16 | F35: -0.18
A36: Interest paid | B36: -4.16 | C36: -2.88 | D36: -1.34 | E36: -3.57 | F36: -6.33
A37: Dividends paid (including tax on dividend) | D37: -0.11 | E37: -0.13 | F37: -0.13
A38: Net Cash Generated from / (Used in) Financing Activities (C) | B38: =SUM(B32:B37) -> -16.38 | C38: =SUM(C32:C37) -> -9.47 | D38: =SUM(D32:D37) -> -2.17 | E38: =SUM(E32:E37) -> 16.89 | F38: =SUM(F32:F37) -> 12.77 | G38: =SUM(G32:G37) -> 0 | H38: =SUM(H32:H37) -> 0 | I38: =SUM(I32:I37) -> 0 | ... K38: =SUM(K32:K37) -> 0
A39: Net Increase / (Decrease) in Cash and Cash Equivalents (A+B+C) | B39: =B38+B30+B24 -> -0.2821 | C39: =C38+C30+C24 -> 4.6886 | D39: =D38+D30+D24 -> 1.9602 | E39: =E38+E30+E24 -> -0.82 | F39: =F38+F30+F24 -> 5.44 | G39: =G38+G30+G24 -> 10.884941 | H39: =H38+H30+H24 -> 11.565298 | I39: =I38+I30+I24 -> 10.219308 | ... K39: =K38+K30+K24 -> 5.7011949
A40: Cash and Cash Equivalents at the beginning of the year (Refer Note-11) | B40: 0.68 | C40: =B41 -> 0.3979 | D40: 5.08 | E40: =D41 -> 7.0402 | F40: =E41 -> 6.2202 | G40: =F41 -> 11.6602 | H40: =G41 -> 22.545141 | I40: =H41 -> 34.110438 | J40: =I41 -> 44.329747 | K40: =J41 -> 52.636565
...

Sheet PL
A1: Particulars | B1: 2021 | C1: 2022 | D1: 2023 | E1: 2024 | F1: 2025
A3: Revenue From Operations | B3: 340.1515 | C3: 547.4973 | D3: 930.09 | E3: 999.14 | F3: 1119.12
A4: Other Income | B4: 3.7787 | C4: 4.5879 | D4: 12.04 | E4: 11.81 | F4: 6.06
A5: Total Income (I+II) | B5: =SUM(B3:B4) -> 343.9302 | C5: =SUM(C3:C4) -> 552.0852 | D5: =SUM(D3:D4) -> 942.13 | E5: =SUM(E3:E4) -> 1010.95 | F5: =SUM(F3:F4) -> 1125.18
A6: Expenses:
A7: Purchase of Stock-In-Trade | B7: 239.3527 | C7: 424.2049 | D7: 756.82 | E7: 775.94 | F7: 853.92
A8: Changes In Inventories of Stock-In-Trade | B8: -3.0071 | C8: -5.5909 | D8: -15.25 | E8: 0.83 | F8: 6.6
A9: Employee Benefits Expenses | B9: 26.0839 | C9: 30.823 | D9: 38.64 | E9: 41.37 | F9: 47.42
A10: Finance Costs | B10: 4.8299 | C10: 2.1703 | D10: 1.34 | E10: 3.5 | F10: 6.14
A11: Depreciation and Amortization Expenses | B11: 13.2735 | C11: 11.7438 | D11: 11.07 | E11: 12.4 | F11: 16.13
A12: Other Expenses | B12: 62.1694 | C12: 85.733 | D12: 140.91 | E12: 166.86 | F12: 187.35
A13: Total Expense (IV) | B13: =SUM(B7:B12) -> 342.7023 | C13: =SUM(C7:C12) -> 549.0841 | D13: =SUM(D7:D12) -> 933.53 | E13: =SUM(E7:E12) -> 1000.9 | F13: =SUM(F7:F12) -> 1117.56
A14: Profit Before Tax (III-IV) | B14: =B5-B13 -> 1.2279 | C14: =C5-C13 -> 3.0011 | D14: =D5-D13 -> 8.6 | E14: =E5-E13 -> 10.05 | F14: =F5-F13 -> 7.62
A15: Tax Expenses
A16: Current Tax | B16: 0.5372 | C16: 0.6686 | D16: 3.17 | E16: 1.91 | F16: 1.52
A17: Deferred Tax Expenses | B17: -0.163 | C17: 0.1354 | D17: -0.73 | E17: 0.63 | F17: 0.37
A18: Total Tax Expenses | B18: =SUM(B16:B17) -> 0.3742 | C18: =SUM(C16:C17) -> 0.804 | D18: =SUM(D16:D17) -> 2.44 | E18: =SUM(E16:E17) -> 2.54 | F18: =SUM(F16:F17) -> 1.89
A19: Profit for the year (V-VI) | B19: =B14-B18 -> 0.8537 | C19: =C14-C18 -> 2.1971 | D19: =D14-D18 -> 6.16 | E19: =E14-E18 -> 7.51 | F19: =F14-F18 -> 5.73
A20: Other Comprehensive Income / (Expense)
A21: Item that will not be reclassified to Profit or Loss
A22: Remeasurement of Defined Benefit Plans | B22: 0.0318 | C22: -0.5051 | D22: -0.36 | E22: -0.51 | F22: -1.22
A23: Tax Expense on Above Items | B23: -0.008 | C23: 0.0083 | D23: 0.09 | E23: 0.13 | F23: 0.31
A24: Item that will be reclassified to Profit or Loss
A25: Fair value changes of Cash flow hedges | F25: -0.64
A26: Tax Expense on Above Items | F26: 0.16
A27: Other Comprehensive Income / (Expense) for the year | B27: =SUM(B21:B26) -> 0.0238 | C27: =SUM(C21:C26) -> -0.4968 | D27: =SUM(D21:D26) -> -0.27 | E27: =SUM(E21:E26) -> -0.38 | F27: =SUM(F21:F26) -> -1.39
A28: Total Comprehensive Income for the year (VII+VIII) | B28: =SUM(B27,B19) -> 0.8775 | C28: =SUM(C27,C19) -> 1.7003 | D28: =SUM(D27,D19) -> 5.89 | E28: =SUM(E27,E19) -> 7.13 | F28: =SUM(F27,F19) -> 4.34
A29: Earnings per Share (Face value of ` 10 each):
A30: Basic | B30: 0.099 | C30: 0.2547 | D30: 71.27 | E30: 87.06 | F30: 66.43
A31: Diluted | B31: 0.099 | C31: 0.2547 | D31: 71.27 | E31: 87.06 | F31: 66.43

Sheet Formated PL
B2: 2021 | C2: 2022 | D2: 2023 | E2: 2024 | F2: 2025 | G2: F2026 | H2: F2027 | I2: F2028 | J2: F2029 | K2: F2030
A3: VOLUME | D3: =(D7*10^7)/D5 -> 66435000 | E3: =(E7*10^7)/E5 -> 68906207 | F3: =(F7*10^7)/F5 -> 72201290 | G3: =F3*(1+G4) -> 75811355 | H3: =G3*(1+H4) -> 79601923 | I3: =H3*(1+I4) -> 83582019 | J3: =I3*(1+J4) -> 87761120 | K3: =J3*(1+K4) -> 92149176
A4: YOY | E4: =E3/D3-1 -> 0.037197364 | F4: =F3/E3-1 -> 0.047819835 | G4: 0.05 | H4: 0.05 | I4: 0.05 | J4: 0.05 | K4: 0.05
A5: AVERAGE PRICE | D5: 140 | E5: 145 | F5: 155 | G5: =F5*(1+G6) -> 162.75 | H5: =G5*(1+H6) -> 170.8875 | I5: =H5*(1+I6) -> 179.43188 | J5: =I5*(1+J6) -> 188.40347 | K5: =J5*(1+K6) -> 197.82364
A6: YOY | E6: =E5/D5-1 -> 0.035714286 | F6: =F5/E5-1 -> 0.068965517 | G6: 0.05 | H6: 0.05 | I6: 0.05 | J6: 0.05 | K6: 0.05
A7: SALES | B7: =PL!B3 -> 340.1515 | C7: =PL!C3 -> 547.4973 | D7: =PL!D3 -> 930.09 | E7: =PL!E3 -> 999.14 | F7: =PL!F3 -> 1119.12 | G7: =(G5*G3)/10^7 -> 1233.8298 | H7: =(H5*H3)/10^7 -> 1360.2974 | I7: =(I5*I3)/10^7 -> 1499.7278 | J7: =(J5*J3)/10^7 -> 1653.4499 | K7: =(K5*K3)/10^7 -> 1822.9286
A8: YOY | C8: =C7/B7-1 -> 0.60956897 | D8: =D7/C7-1 -> 0.6988029 | E8: =E7/D7-1 -> 0.074240127 | F8: =F7/E7-1 -> 0.12008327 | G8: =G7/F7-1 -> 0.1025 | H8: =H7/G7-1 -> 0.1025 | I8: =I7/H7-1 -> 0.1025 | J8: =J7/I7-1 -> 0.1025 | K8: =K7/J7-1 -> 0.1025
A9: COGS | B9: =SUM(PL!B7:B8) -> 236.3456 | C9: =SUM(PL!C7:C8) -> 418.614 | D9: =SUM(PL!D7:D8) -> 741.57 | E9: =SUM(PL!E7:E8) -> 776.77 | F9: =SUM(PL!F7:F8) -> 860.52 | G9: =G10*G7 -> 925.37235 | H9: =H10*H7 -> 1020.223 | I9: =I10*I7 -> 1124.7959 | J9: =J10*J7 -> 1240.0875 | K9: =K10*K7 -> 1367.1964
A10: AS%OF SALES | B10: =B9/B7 -> 0.69482451 | C10: =C9/C7 -> 0.76459555 | D10: =D9/D7 -> 0.79730994 | E10: =E9/E7 -> 0.7774386 | F10: =F9/F7 -> 0.76892558 | G10: 0.75 | H10: 0.75 | I10: 0.75 | J10: 0.75 | K10: 0.75
A11: GROSS PROFIT | B11: =B7-B9 -> 103.8059 | C11: =C7-C9 -> 128.8833 | D11: =D7-D9 -> 188.52 | E11: =E7-E9 -> 222.37 | F11: =F7-F9 -> 258.6 | G11: =G7-G9 -> 308.45745 | H11: =H7-H9 -> 340.07434 | I11: =I7-I9 -> 374.93196 | ... K11: =K7-K9 -> 455.73214
A12: GROSS MARGIN | B12: =B11/B$7 -> 0.30517549 | C12: =C11/C$7 -> 0.23540445 | D12: =D11/D$7 -> 0.20269006 | E12: =E11/E$7 -> 0.2225614 | F12: =F11/F$7 -> 0.23107442 | G12: =G11/G$7 -> 0.25 | H12: =H11/H$7 -> 0.25 | I12: =I11/I$7 -> 0.25 | ... K12: =K11/K$7 -> 0.25
A14: EMPLOYE EXPENDITURE | B14: =PL!B9 -> 26.0839 | C14: =PL!C9 -> 30.823 | D14: =PL!D9 -> 38.64 | E14: =PL!E9 -> 41.37 | F14: =PL!F9 -> 47.42 | G14: =F14*(1+G15) -> 55.0072 | H14: =G14*(1+H15) -> 63.808352 | I14: =H14*(1+I15) -> 74.017688 | J14: =I14*(1+J15) -> 85.860518 | K14: =J14*(1+K15) -> 99.598201
A15: YOY | C15: =C14/B14-1 -> 0.18168679 | D15: =D14/C14-1 -> 0.25360932 | E15: =E14/D14-1 -> 0.070652174 | F15: =F14/E14-1 -> 0.14624124 | G15: 0.16 | H15: 0.16 | I15: 0.16 | J15: 0.16 | K15: 0.16
A16: OTHER EXPENDITURE | B16: =PL!B12 -> 62.1694 | C16: =PL!C12 -> 85.733 | D16: =PL!D12 -> 140.91 | E16: =PL!E12 -> 166.86 | F16: =PL!F12 -> 187.35 | G16: =G17*G$7 -> 209.75107 | H16: =H17*H$7 -> 231.25055 | I16: =I17*I$7 -> 254.95373 | J16: =J17*J$7 -> 281.08649 | K16: =K17*K$7 -> 309.89785
A17: AS%OF SALES | B17: =B16/B$7 -> 0.18276974 | C17: =C16/C$7 -> 0.15659073 | D17: =D16/D$7 -> 0.15150147 | E17: =E16/E$7 -> 0.16700362 | F17: =F16/F$7 -> 0.16740832 | G17: 0.17 | H17: 0.17 | I17: 0.17 | J17: 0.17 | K17: 0.17
A18: EBITDA | B18: =B11-B14-B16 -> 15.5526 | C18: =C11-C14-C16 -> 12.3273 | D18: =D11-D14-D16 -> 8.97 | E18: =E11-E14-E16 -> 14.14 | F18: =F11-F14-F16 -> 23.83 | G18: =G11-G14-G16 -> 43.699184 | H18: =H11-H14-H16 -> 45.015436 | I18: =I11-I14-I16 -> 45.960538 | ... K18: =K11-K14-K16 -> 46.236083
A19: EBITDA MARGIN | B19: =B18/B$7 -> 0.045722568 | C19: =C18/C$7 -> 0.022515727 | D19: =D18/D$7 -> 0.009644228 | E19: =E18/E$7 -> 0.014152171 | F19: =F18/F$7 -> 0.021293516 | G19: =G18/G$7 -> 0.035417514 | H19: =H18/H$7 -> 0.03309235 | I19: =I18/I$7 -> 0.030645919 | ... K19: =K18/K$7 -> 0.025363629
A20: DEPRICITATION | B20: =PL!B11 -> 13.2735 | C20: =PL!C11 -> 11.7438 | D20: =PL!D11 -> 11.07 | E20: =PL!E11 -> 12.4 | F20: =PL!F11 -> 16.13 | G20: ='PPE NOTE'!E11 -> 17.760415 | H20: ='PPE NOTE'!F11 -> 20.102847 | I20: ='PPE NOTE'!G11 -> 22.685378 | J20: ='PPE NOTE'!H11 -> 25.532619 | K20: ='PPE NOTE'!I11 -> 28.671702
A21: YoY | C21: =C20/B20-1 -> -0.11524466 | D21: =D20/C20-1 -> -0.057374955 | E21: =E20/D20-1 -> 0.12014453 | F21: =F20/E20-1 -> 0.30080645 | G21: =G20/F20-1 -> 0.10107966 | H21: =H20/G20-1 -> 0.13189061 | I21: =I20/H20-1 -> 0.12846595 | J21: =J20/I20-1 -> 0.12550995 | K21: =K20/J20-1 -> 0.12294403
A22: EBIT | B22: =B18-B20 -> 2.2791 | C22: =C18-C20 -> 0.5835 | D22: =D18-D20 -> -2.1 | E22: =E18-E20 -> 1.74 | F22: =F18-F20 -> 7.7 | G22: =G18-G20 -> 25.938769 | H22: =H18-H20 -> 24.912589 | I22: =I18-I20 -> 23.27516 | ... K22: =K18-K20 -> 17.564381
A23: EBIT MARGIN | B23: =B22/B$7 -> 0.0067002497 | C23: =C22/C$7 -> 0.0010657587 | D23: =D22/D$7 -> -0.002257846 | E23: =E22/E$7 -> 0.0017414977 | F23: =F22/F$7 -> 0.006880406 | G23: =G22/G$7 -> 0.021022972 | H23: =H22/H$7 -> 0.018314076 | I23: =I22/I$7 -> 0.015519589 | ... K23: =K22/K$7 -> 0.0096352547
A24: INTREST | B24: =PL!B10 -> 4.8299 | C24: =PL!C10 -> 2.1703 | D24: =PL!D10 -> 1.34 | E24: =PL!E10 -> 3.5 | F24: =PL!F10 -> 6.14 | G24: =F24 -> 6.14 | H24: =G24 -> 6.14 | I24: =H24 -> 6.14 | J24: =I24 -> 6.14 | K24: =J24 -> 6.14
A25: YoY | C25: =C24/B24-1 -> -0.55065322 | D25: =D24/C24-1 -> -0.38257384 | E25: =E24/D24-1 -> 1.6119403 | F25: =F24/E24-1 -> 0.75428571 | G25: =G24/F24-1 -> 0 | H25: =H24/G24-1 -> 0 | I25: =I24/H24-1 -> 0 | J25: =J24/I24-1 -> 0 | K25: =K24/J24-1 -> 0
A26: OTHER INCOME | B26: =PL!B4 -> 3.7787 | C26: =PL!C4 -> 4.5879 | D26: =PL!D4 -> 12.04 | E26: =PL!E4 -> 11.81 | F26: =PL!F4 -> 6.06 | G26: =F26 -> 6.06 | H26: =G26 -> 6.06 | I26: =H26 -> 6.06 | J26: =I26 -> 6.06 | K26: =J26 -> 6.06
A27: EBT | B27: =B22+B26-B24 -> 1.2279 | C27: =C22+C26-C24 -> 3.0011 | D27: =D22+D26-D24 -> 8.6 | E27: =E22+E26-E24 -> 10.05 | F27: =F22+F26-F24 -> 7.62 | G27: =G22+G26-G24 -> 25.858769 | H27: =H22+H26-H24 -> 24.832589 | I27: =I22+I26-I24 -> 23.19516 | ... K27: =K22+K26-K24 -> 17.484381
A28: EBT MARGIN | B28: =B27/B$7 -> 0.0036098621 | C28: =C27/C$7 -> 0.0054814882 | D28: =D27/D$7 -> 0.009246417 | E28: =E27/E$7 -> 0.01005865 | F28: =F27/F$7 -> 0.0068089213 | G28: =G27/G$7 -> 0.020958133 | H28: =H27/H$7 -> 0.018255266 | I28: =I27/I$7 -> 0.015466246 | ... K28: =K27/K$7 -> 0.0095913693
A29: TAX | B29: =PL!B18 -> 0.3742 | C29: =PL!C18 -> 0.804 | D29: =PL!D18 -> 2.44 | E29: =PL!E18 -> 2.54 | F29: =PL!F18 -> 1.89 | G29: =G30*G27 -> 6.9818677 | H29: =H30*H27 -> 6.7047991 | I29: =I30*I27 -> 6.2626932 | J29: =J30*J27 -> 5.6167715 | K29: =K30*K27 -> 4.7207828
A30: TAX RATE | B30: =B29/B27 -> 0.30474794 | C30: =C29/C27 -> 0.26790177 | D30: =D29/D27 -> 0.28372093 | E30: =E29/E27 -> 0.25273632 | F30: =F29/F27 -> 0.2480315 | G30: 0.27 | H30: 0.27 | I30: 0.27 | J30: 0.27 | K30: 0.27
A31: PAT | B31: =B27-B29 -> 0.8537 | C31: =C27-C29 -> 2.1971 | D31: =D27-D29 -> 6.16 | E31: =E27-E29 -> 7.51 | F31: =F27-F29 -> 5.73 | G31: =G27-G29 -> 18.876901 | H31: =H27-H29 -> 18.12779 | I31: =I27-I29 -> 16.932467 | ... K31: =K27-K29 -> 12.763598
A32: PAT MARGIN | B32: =B31/B$7 -> 0.002509764 | C32: =C31/C$7 -> 0.0040129878 | D32: =D31/D$7 -> 0.006623015 | E32: =E31/E$7 -> 0.0075164642 | F32: =F31/F$7 -> 0.0051200944 | G32: =G31/G$7 -> 0.015299437 | H32: =H31/H$7 -> 0.013326344 | I32: =I31/I$7 -> 0.01129036 | ... K32: =K31/K$7 -> 0.0070016996
A33: FV | B33: 10 | C33: 10 | D33: 10 | E33: 10 | F33: 10 | G33: 10 | H33: 10 | I33: 10 | J33: 10 | K33: 10
A34: Number of shares | B34: =BS!B29 -> 0.8627 | C34: =BS!C29 -> 0.8627 | D34: =BS!D29 -> 0.86 | E34: =BS!E29 -> 0.86 | F34: =BS!F29 -> 0.86 | G34: =F34 -> 0.86 | H34: =G34 -> 0.86 | I34: =H34 -> 0.86 | J34: =I34 -> 0.86 | K34: =J34 -> 0.86
A35: EPS | B35: =B31/B34 -> 0.98956764 | C35: =C31/C34 -> 2.5467718 | D35: =D31/D34 -> 7.1627907 | E35: =E31/E34 -> 8.7325581 | F35: =F31/F34 -> 6.6627907 | G35: =G31/G34 -> 21.949885 | H35: =H31/H34 -> 21.078826 | I35: =I31/I34 -> 19.688915 | ... K35: =K31/K34 -> 14.841393
A36: YoY | C36: =C35/B35-1 -> 1.5736207 | D36: =D35/C35-1 -> 1.8124981 | E36: =E35/D35-1 -> 0.21915584 | F36: =F35/E35-1 -> -0.23701731 | G36: =G35/F35-1 -> 2.2943982 | H36: =H35/G35-1 -> -0.039684011 | I36: =I35/H35-1 -> -0.065938727 | J36: =J35/I35-1 -> -0.10313801 | K36: =K35/J35-1 -> -0.15952022

Sheet WC Note
A1: Working capital Note
A2: Particulars in Rs Cr | B2: ='[1]FOMATED P&L'!B2 -> 2021 | C2: ='[1]FOMATED P&L'!C2 -> 2022 | D2: ='[1]FOMATED P&L'!D2 -> 2023 | E2: ='[1]FOMATED P&L'!E2 -> 2024 | F2: ='[1]FOMATED P&L'!F2 -> 2025 | G2: ='[1]FOMATED P&L'!G2 -> F2026 | H2: ='[1]FOMATED P&L'!H2 -> F2027 | I2: ='[1]FOMATED P&L'!I2 -> F2028 | ... K2: ='[1]FOMATED P&L'!K2 -> F2030
A4: Sales | B4: ='Formated PL'!B7 -> 340.1515 | C4: ='Formated PL'!C7 -> 547.4973 | D4: ='Formated PL'!D7 -> 930.09 | E4: ='Formated PL'!E7 -> 999.14 | F4: ='Formated PL'!F7 -> 1119.12 | G4: ='Formated PL'!G7 -> 1233.8298 | H4: ='Formated PL'!H7 -> 1360.2974 | I4: ='Formated PL'!I7 -> 1499.7278 | ... K4: ='Formated PL'!K7 -> 1822.9286
A5: COGS | B5: ='Formated PL'!B9 -> 236.3456 | C5: ='Formated PL'!C9 -> 418.614 | D5: ='Formated PL'!D9 -> 741.57 | E5: ='Formated PL'!E9 -> 776.77 | F5: ='Formated PL'!F9 -> 860.52 | G5: ='Formated PL'!G9 -> 925.37235 | H5: ='Formated PL'!H9 -> 1020.223 | I5: ='Formated PL'!I9 -> 1124.7959 | ... K5: ='Formated PL'!K9 -> 1367.1964
A6: COGS | B6: =B5 -> 236.3456 | C6: =C5 -> 418.614 | D6: =D5 -> 741.57 | E6: =E5 -> 776.77 | F6: =F5 -> 860.52 | G6: =G5 -> 925.37235 | H6: =H5 -> 1020.223 | I6: =I5 -> 1124.7959 | ... K6: =K5 -> 1367.1964
A8: Receivables | B8: =BS!B19 -> 26.8101 | C8: =BS!C19 -> 15.3965 | D8: =BS!D19 -> 38.47 | E8: =BS!E19 -> 47.99 | F8: =BS!F19 -> 57.28 | G8: =(G12*G4/365) -> 63.1512 | H8: =H12*H4/365 -> 69.624198 | I8: =I12*I4/365 -> 76.760678 | J8: =J12*J4/365 -> 84.628648 | K8: =K12*K4/365 -> 93.303084
A9: Inventory | B9: =BS!B17 -> 28.0477 | C9: =BS!C17 -> 33.7302 | D9: =BS!D17 -> 49.1 | E9: =BS!E17 -> 48.12 | F9: =BS!F17 -> 41.52 | G9: =(G13*G5/365) -> 44.649119 | H9: =H13*H5/365 -> 49.225654 | I9: =I13*I5/365 -> 54.271283 | J9: =J13*J5/365 -> 59.83409 | K9: =K13*K5/365 -> 65.967084
A10: Payables | B10: =BS!B46 -> 38.4727 | C10: =BS!C46 -> 50.3345 | D10: =BS!D46 -> 88.24 | E10: =BS!E46 -> 90.81 | F10: =BS!F46 -> 105.15 | G10: =(G14*G6/365) -> 113.07454 | H10: =(H14*H6/365) -> 124.66468 | I10: =(I14*I6/365) -> 137.44281 | J10: =(J14*J6/365) -> 151.5307 | K10: =(K14*K6/365) -> 167.06259
A12: Days of Receivables | B12: =365*B8/B4 -> 28.768612 | C12: =365*C8/C4 -> 10.264384 | D12: =365*D8/D4 -> 15.09698 | E12: =365*E8/E4 -> 17.531427 | F12: =365*F8/F4 -> 18.681821 | G12: 18.681821 | H12: =G12 -> 18.681821 | I12: =H12 -> 18.681821 | J12: =I12 -> 18.681821 | K12: =J12 -> 18.681821
A13: Days of Inventory | B13: =365*B9/B5 -> 43.315427 | C13: =365*C9/C5 -> 29.410204 | D13: =365*D9/D5 -> 24.16697 | E13: =365*E9/E5 -> 22.611326 | F13: =365*F9/F5 -> 17.611212 | G13: 17.611212 | H13: =G13 -> 17.611212 | I13: =H13 -> 17.611212 | J13: =I13 -> 17.611212 | K13: =J13 -> 17.611212
A14: Days of Payables | B14: =365*B10/B6 -> 59.415261 | C14: =365*C10/C6 -> 43.887907 | D14: =365*D10/D6 -> 43.431638 | E14: =365*E10/E6 -> 42.671125 | F14: =365*F10/F6 -> 44.600648 | G14: 44.600648 | H14: =G14 -> 44.600648 | I14: =H14 -> 44.600648 | J14: =I14 -> 44.600648 | K14: =J14 -> 44.600648

Sheet PPE NOTE
A1: PPE | B1: ='[1]FOMATED P&L'!D2 -> 2023 | C1: ='[1]FOMATED P&L'!E2 -> 2024 | D1: ='[1]FOMATED P&L'!F2 -> 2025 | E1: ='[1]FOMATED P&L'!G2 -> F2026 | F1: ='[1]FOMATED P&L'!H2 -> F2027 | G1: ='[1]FOMATED P&L'!I2 -> F2028 | H1: ='[1]FOMATED P&L'!J2 -> F2029 | I1: ='[1]FOMATED P&L'!K2 -> F2030
A2: Gross Assets
A3: Opening balance | B3: 118.35 | C3: =B6 -> 116.45 | D3: =C6 -> 144.63 | E3: =D6 -> 181.6 | F3: =E6 -> 206.2766 | G3: =F6 -> 233.48254 | H3: =G6 -> 263.4771 | I3: =H6 -> 296.5461
A4: Add: Capex | B4: 7.58 | C4: 37.48 | D4: 46.21 | E4: =(E20*'Formated PL'!G7) -> 24.676596 | F4: =F20*'Formated PL'!H7 -> 27.205947 | G4: =G20*'Formated PL'!I7 -> 29.994557 | H4: =H20*'Formated PL'!J7 -> 33.068999 | I4: =I20*'Formated PL'!K7 -> 36.458571
A5: Less: Sold | B5: -9.48 | C5: -9.3 | D5: -9.24
A6: Closing balance | B6: =SUM(B3:B5) -> 116.45 | C6: =SUM(C3:C5) -> 144.63 | D6: =SUM(D3:D5) -> 181.6 | E6: =SUM(E3:E5) -> 206.2766 | F6: =SUM(F3:F5) -> 233.48254 | G6: =SUM(G3:G5) -> 263.4771 | H6: =SUM(H3:H5) -> 296.5461 | I6: =SUM(I3:I5) -> 333.00467
A9: Depreciation Schedule
A10: Opening balance | B10: 71.95 | C10: =B13 -> 74.83 | D10: =C13 -> 78.88 | E10: =D13 -> 87.02 | F10: =E13 -> 104.78041 | G10: =F13 -> 124.88326 | H10: =G13 -> 147.56864 | I10: =H13 -> 173.10126
A11: Add: Depreciation For the year | B11: 10.52 | C11: 11.81 | D11: 15.66 | E11: =E19*E6 -> 17.760415 | F11: =F19*F6 -> 20.102847 | G11: =G19*G6 -> 22.685378 | H11: =H19*H6 -> 25.532619 | I11: =I19*I6 -> 28.671702
A12: Adjustments
A13: Closing balance | B13: 74.83 | C13: 78.88 | D13: 87.02 | E13: =SUM(E10:E12) -> 104.78041 | F13: =SUM(F10:F12) -> 124.88326 | G13: =SUM(G10:G12) -> 147.56864 | H13: =SUM(H10:H12) -> 173.10126 | I13: =SUM(I10:I12) -> 201.77296
A16: Net assets ( Gross - Accumulated Depreciation) | B16: =B6-B13 -> 41.62 | C16: =C6-C13 -> 65.75 | D16: =D6-D13 -> 94.58 | E16: =E6-E13 -> 101.49618 | F16: =F6-F13 -> 108.59928 | G16: =G6-G13 -> 115.90846 | H16: =H6-H13 -> 123.44484 | I16: =I6-I13 -> 131.23171
A19: Depreciation Rate | B19: =B11/B6 -> 0.090339201 | C19: =C11/C6 -> 0.081656641 | D19: =D11/D6 -> 0.08623348 | E19: 0.0861 | F19: =E19 -> 0.0861 | G19: =F19 -> 0.0861 | H19: =G19 -> 0.0861 | I19: =H19 -> 0.0861
A20: Capex as % of sales | B20: =B4/'Formated PL'!D7 -> 0.0081497489 | C20: =C4/'Formated PL'!E7 -> 0.037512261 | D20: =D4/'Formated PL'!F7 -> 0.041291372 | E20: 0.02 | F20: =E20 -> 0.02 | G20: =F20 -> 0.02 | H20: =G20 -> 0.02 | I20: =H20 -> 0.02

Sheet Other Equity
A1: Particulars in Cr | B1: ='Formated PL'!B2 -> 2021 | C1: ='Formated PL'!C2 -> 2022 | D1: ='Formated PL'!D2 -> 2023 | E1: ='Formated PL'!E2 -> 2024 | F1: ='Formated PL'!F2 -> 2025 | G1: ='Formated PL'!G2 -> F2026 | H1: ='Formated PL'!H2 -> F2027 | I1: ='Formated PL'!I2 -> F2028 | ... K1: ='Formated PL'!K2 -> F2030
A2: Opening balance | B2: 0 | G2: =F5 -> 21.41 | H2: =G5 -> 40.286901 | I2: =H5 -> 58.414692 | J2: =I5 -> 75.347159 | K2: =J5 -> 90.533244
A3: Add: Profit for the year | B3: ='Formated PL'!B31 -> 0.8537 | C3: ='Formated PL'!C31 -> 2.1971 | D3: ='Formated PL'!D31 -> 6.16 | E3: ='Formated PL'!E31 -> 7.51 | F3: ='Formated PL'!F31 -> 5.73 | G3: ='Formated PL'!G31 -> 18.876901 | H3: ='Formated PL'!H31 -> 18.12779 | I3: ='Formated PL'!I31 -> 16.932467 | ... K3: ='Formated PL'!K31 -> 12.763598
A4: Less: Dividends | B4: =CF!B37 -> 0 | C4: =CF!C37 -> 0 | D4: =CF!D37 -> -0.11 | E4: =CF!E37 -> -0.13 | F4: =CF!F37 -> -0.13
A5: Closing balance | B5: =BS!B30 -> 2.7236 | C5: =BS!C30 -> 4.4239 | D5: =BS!D30 -> 10.2 | E5: =BS!E30 -> 17.2 | F5: =BS!F30 -> 21.41 | G5: =SUM(G2:G4) -> 40.286901 | H5: =SUM(H2:H4) -> 58.414692 | I5: =SUM(I2:I4) -> 75.347159 | J5: =SUM(J2:J4) -> 90.533244 | K5: =SUM(K2:K4) -> 103.29684
A8: Dividend payout ratio | B8: =-B4/B3 -> 0 | C8: =-C4/C3 -> 0 | D8: =-D4/D3 -> 0.017857143 | E8: =-E4/E3 -> 0.017310253 | F8: =-F4/F3 -> 0.022687609 | G8: =-G4/G3 -> 0 | H8: =-H4/H3 -> 0 | I8: =-I4/I3 -> 0 | ... K8: =-K4/K3 -> 0

Sheet Revenue Breakup
B1: Revenue Breakups | C1: Rupees | E1: Sales | F1: in Cr. | G1: AVG PRICE | H1: Sale Quantity | I1: Growth in AVG price | J1: Growth In quantity
B2: Gourmet/Natural Tubs (1 Litre): ₹220 - ₹320 | C2: 280 | E2: 2030 | F2: =(G2*H2)/10^7 -> 1737.7602 | G2: =G3*(1+I2) -> 197.82364 | H2: =H3*(1+J2) -> 87843909 | I2: 0.05 | J2: 0.04
B3: Premium Tubs (700ml - 750ml): ₹180 - ₹250 | C3: 220 | E3: 2029 | F3: =(G3*H3)/10^7 -> 1591.3555 | G3: =G4*(1+I3) -> 188.40347 | H3: =H4*(1+J3) -> 84465298 | I3: 0.05 | J3: 0.04
B4: Ice Cream Cakes (500ml): ₹210 - ₹340 | C4: 290 | E4: 2028 | F4: =(G4*H4)/10^7 -> 1457.2853 | G4: =G5*(1+I4) -> 179.43188 | H4: =H5*(1+J4) -> 81216632 | I4: 0.05 | J4: 0.04
B5: Cones & Flingos: ₹30 - ₹55 | C5: 40 | E5: 2027 | F5: =(G5*H5)/10^7 -> 1334.5103 | G5: =G6*(1+I5) -> 170.8875 | H5: =H6*(1+J5) -> 78092916 | I5: 0.05 | J5: 0.04
B6: Cups: ₹45 - ₹60 | C6: 50 | E6: 2026 | F6: =(G6*H6)/10^7 -> 1222.079 | G6: =G7*(1+I6) -> 162.75 | H6: =H7*(1+J6) -> 75089342 | I6: 0.05 | J6: 0.04
B7: Kulfi Sticks: ₹45 - ₹60 | C7: 50 | E7: 2025 | F7: ='Formated PL'!F7 -> 1119.12 | G7: 155 | H7: =(F7*10^7)/G7 -> 72201290 | I7: 0.07 | J7: 0.05
B8: AVG PRICE | C8: 155 | E8: 2024 | F8: ='Formated PL'!E7 -> 999.14 | G8: 145 | H8: =(F8*10^7)/G8 -> 68906207 | I8: 0.04 | J8: 0.04
E9: 2023 | F9: ='Formated PL'!D7 -> 930.09 | G9: 140 | H9: =(F9*10^7)/G9 -> 66435000

Sheet WACC
B1: ='Formated PL'!B2 -> 2021 | C1: ='Formated PL'!C2 -> 2022 | D1: ='Formated PL'!D2 -> 2023 | E1: ='Formated PL'!E2 -> 2024 | F1: ='Formated PL'!F2 -> 2025 | G1: ='Formated PL'!G2 -> F2026
A3: Total Equity | B3: =BS!B31 -> 3.5863 | C3: =BS!C31 -> 5.2866 | D3: =BS!D31 -> 11.06 | E3: =BS!E31 -> 18.06 | F3: =BS!F31 -> 22.27 | G3: =BS!G31 -> 41.146901
A4: Total Debt | B4: =BS!B35+BS!B42 -> 12.5533 | C4: =BS!C35+BS!C42 -> 5.9929 | D4: =BS!D35+BS!D42 -> 5.36 | E4: =BS!E35+BS!E42 -> 25.94 | F4: =BS!F35+BS!F42 -> 45.24 | G4: =BS!G35+BS!G42 -> 45.24
A5: Interest expense | B5: ='Formated PL'!B24 -> 4.8299 | C5: ='Formated PL'!C24 -> 2.1703 | D5: ='Formated PL'!D24 -> 1.34 | E5: ='Formated PL'!E24 -> 3.5 | F5: ='Formated PL'!F24 -> 6.14 | G5: ='Formated PL'!G24 -> 6.14
A6: Cost of debt (interest rate) | B6: =B5/B4 -> 0.38475142 | C6: =C5/C4 -> 0.36214521 | D6: =D5/D4 -> 0.25 | E6: =E5/E4 -> 0.13492675 | F6: =F5/F4 -> 0.1357206 | G6: =G5/G4 -> 0.1357206
A7: Tax rate | B7: ='Formated PL'!B30 -> 0.30474794 | C7: ='Formated PL'!C30 -> 0.26790177 | D7: ='Formated PL'!D30 -> 0.28372093 | E7: ='Formated PL'!E30 -> 0.25273632 | F7: ='Formated PL'!F30 -> 0.2480315 | G7: ='Formated PL'!G30 -> 0.27
A8: ROE | B8: ='Formated PL'!B31/WACC!B3 -> 0.23804478 | C8: ='Formated PL'!C31/WACC!C3 -> 0.41559793 | D8: ='Formated PL'!D31/WACC!D3 -> 0.55696203 | E8: ='Formated PL'!E31/WACC!E3 -> 0.4158361 | F8: ='Formated PL'!F31/WACC!F3 -> 0.25729681 | G8: ='Formated PL'!G31/WACC!G3 -> 0.45876848
A10: Interest coverage | B10: ='Formated PL'!B22/'Formated PL'!B24 -> 0.47187312 | C10: ='Formated PL'!C22/'Formated PL'!C24 -> 0.26885684 | D10: ='Formated PL'!D22/'Formated PL'!D24 -> -1.5671642 | E10: ='Formated PL'!E22/'Formated PL'!E24 -> 0.49714286 | F10: ='Formated PL'!F22/'Formated PL'!F24 -> 1.2540717 | G10: ='Formated PL'!G22/'Formated PL'!G24 -> 4.2245552
A12: After tax cost of debt | B12: =B6*(1-B7) -> 0.26749922 | C12: =C6*(1-C7) -> 0.26512586 | D12: =D6*(1-D7) -> 0.17906977 | E12: =E6*(1-E7) -> 0.10082586 | F12: =F6*(1-F7) -> 0.10205762 | G12: =G6*(1-G7) -> 0.099076039
A14: Debt/Equity | B14: =B4/B3 -> 3.5003485 | C14: =C4/C3 -> 1.1336019 | D14: =D4/D3 -> 0.48462929 | E14: =E4/E3 -> 1.4363234 | F14: =F4/F3 -> 2.0314324 | G14: =G4/G3 -> 1.0994753
A16: Weights
A17: Equity | G17: =1-G18 -> 0.4763095
A18: Debt | G18: =G14/(1+G14) -> 0.5236905
A20: CAPM
A21: Rf | G21: 0.067
A22: B | G22: 0.85
A23: RM-RF | G23: 0.07
A24: Cost of equity | G24: =G21+(G22*G23) -> 0.1265
A26: WACC | G26: =G24*G17+G18*G12 -> 0.11213833

Sheet FCFF
A1: FCFF | B1: ='Formated PL'!B2 -> 2021 | C1: ='Formated PL'!C2 -> 2022 | D1: ='Formated PL'!D2 -> 2023 | E1: ='Formated PL'!E2 -> 2024 | F1: ='Formated PL'!F2 -> 2025 | G1: ='Formated PL'!G2 -> F2026 | H1: ='Formated PL'!H2 -> F2027 | I1: ='Formated PL'!I2 -> F2028 | ... K1: ='Formated PL'!K2 -> F2030
O2: =F17 -> 622.48326 | P2: 0.091 | Q2: 0.101 | R2: 0.112 | S2: 0.121
A3: EBIT*(1-Tax rate) | B3: ='Formated PL'!B22*(1-'Formated PL'!B30) -> 1.584549 | C3: ='Formated PL'!C22*(1-'Formated PL'!C30) -> 0.42717932 | D3: ='Formated PL'!D22*(1-'Formated PL'!D30) -> -1.504186 | E3: ='Formated PL'!E22*(1-'Formated PL'!E30) -> 1.3002388 | F3: ='Formated PL'!F22*(1-'Formated PL'!F30) -> 5.7901575 | G3: ='Formated PL'!G22*(1-'Formated PL'!G30) -> 18.935301 | H3: ='Formated PL'!H22*(1-'Formated PL'!H30) -> 18.18619 | I3: ='Formated PL'!I22*(1-'Formated PL'!I30) -> 16.990867 | ... K3: ='Formated PL'!K22*(1-'Formated PL'!K30) -> 12.821998 | O3: 0.08 | P3: 673.11286 | Q3: 359.99686 | R3: 241.59987 | S3: 191.98339
A4: Add: Depreciation | B4: ='Formated PL'!B20 -> 13.2735 | C4: ='Formated PL'!C20 -> 11.7438 | D4: ='Formated PL'!D20 -> 11.07 | E4: ='Formated PL'!E20 -> 12.4 | F4: ='Formated PL'!F20 -> 16.13 | G4: ='Formated PL'!G20 -> 17.760415 | H4: ='Formated PL'!H20 -> 20.102847 | I4: ='Formated PL'!I20 -> 22.685378 | ... K4: ='Formated PL'!K20 -> 28.671702 | M4: WACC | N4: =WACC!G26 -> 0.11213833 | O4: 0.09 | P4: 7315.5209 | Q4: 679.20122 | R4: 347.38524 | S4: 251.05157
A5: Change in Working capital | B5: =CF!B22 -> -0.88 | C5: =CF!C22 -> 12.9775 | D5: =CF!D22 -> -0.8298 | E5: =CF!E22 -> 6.03 | F5: =CF!F22 -> 9.52 | G5: =CF!G22 -> -1.0757798 | H5: =CF!H22 -> 0.54060758 | I5: =CF!I22 -> 0.59601985 | ... K5: =CF!K22 -> 0.72446585 | M5: Growth | N5: 0.1 | O5: 0.1 | P5: -802.97782 | Q5: 7382.4929 | R5: 629.47956 | S5: 366.37515
A6: Less: Capex | B6: =CF!B26 -> -3.99 | C6: =CF!C26 -> -13.38 | D6: =CF!D26 -> -6.63 | E6: =CF!E26 -> -38.2 | F6: =CF!F26 -> -43.96 | G6: =CF!G26 -> -24.676596 | H6: =CF!H26 -> -27.205947 | I6: =CF!I26 -> -29.994557 | ... K6: =CF!K26 -> -36.458571 | O6: 0.11 | P6: -375.68841 | Q6: -810.41916 | R6: 3732.5171 | S6: 691.37796
A7: FCFF | B7: =SUM(B3:B6) -> 9.988049 | C7: =SUM(C3:C6) -> 11.768479 | D7: =SUM(D3:D6) -> 2.106014 | E7: =SUM(E3:E6) -> -18.469761 | F7: =SUM(F3:F6) -> -12.519843 | G7: =SUM(G3:G6) -> 10.943341 | H7: =SUM(H3:H6) -> 11.623698 | I7: =SUM(I3:I6) -> 10.277708 | ... K7: =SUM(K3:K6) -> 5.7595949 | O7: 0.12 | P7: -243.08136 | Q7: -379.21326 | R7: -922.03921 | S7: 7516.437
A8: Terminal Value | K8: =K7*(1+N5)/(N4-N5) -> 521.94605
A9: Total Cash flow | G9: =SUM(G7:G8) -> 10.943341 | H9: =SUM(H7:H8) -> 11.623698 | I9: =SUM(I7:I8) -> 10.277708 | J9: =SUM(J7:J8) -> 8.3652181 | K9: =SUM(K7:K8) -> 527.70564
A11: Present Value of all cash flows = Enterprise Value | F11: =SUM(G9:K9) -> 568.91561
A12: Less: Debt | F12: =WACC!F4 -> 45.24
A13: Add: Cash | F13: =BS!F20 -> 11.66
A14: Equity Value | F14: =F11-F12+F13 -> 535.33561
A16: Number of shares | F16: ='Formated PL'!F34 -> 0.86
A17: Intrinsic Value (Per share Value) | F17: =F14/F16 -> 622.48326
A18: Current Price | F18: =INDEX!L5 -> 9999
F19: =F17/F18-1 -> -0.93774545
